<?xml version="1.0"?>
<robot name="inchworm">
  <link name="world" />

  <!-- End effector attached to world -->
  <link name="iw_foot_bottom">
    <inertial>
      <mass value="0.151" />
      <inertia ixx="3.8554e-05" ixy="9.4075e-07" ixz="1.709e-06" iyy="4.445e-05" iyz="1.2246e-06" izz="2.5729e-05"/>
    </inertial>
    <visual>
      <geometry>
        <mesh filename="package://inchworm_description/media/link0.stl" scale="0.001 0.001 0.001" />
      </geometry>
      <material name="blue">
        <color rgba="0.113 0.321 0.678 1.0" />
      </material>
    </visual>
    <collision>
      <origin xyz="0 0 -0.027685" rpy="0 0 0" />
      <geometry>
        <box size="0.07 0.07 0.05463" />
      </geometry>
    </collision>
  </link>

  <!-- Link attached to EE -->
  <link name="iw_ankle_bottom">
    <inertial>
      <mass value="0.151" />
      <inertia ixx="3.8554e-05" ixy="9.4075e-07" ixz="1.709e-06" iyy="4.445e-05" iyz="1.2246e-06" izz="2.5729e-05"/>
    </inertial>
    <visual>
      <geometry>
        <mesh filename="package://inchworm_description/media/link1.stl" scale="0.001 0.001 0.001" />
      </geometry>
      <material name="blue">
        <color rgba="0.113 0.321 0.678 1.0" />
      </material>
    </visual>
    <collision>
      <origin xyz="0 -0.02 0" rpy="0 0 0" />
      <geometry>
        <box size="0.045 0.08 0.08" />
      </geometry>
    </collision>
  </link>

  <!-- First big link -->
  <link name="iw_beam_bottom">
    <origin xyz="0 0 0" rpy="0 0 3.14" />
    <inertial>
      <mass value="0.151" />
      <inertia ixx="3.8554e-05" ixy="9.4075e-07" ixz="1.709e-06" iyy="4.445e-05" iyz="1.2246e-06" izz="2.5729e-05"/>
    </inertial>
    <visual>
      <origin xyz="0.165 0 0" rpy="0 0 0" />
      <geometry>
        <mesh filename="package://inchworm_description/media/link2.stl" scale="0.001 0.001 0.001" />
      </geometry>
      <material name="blue">
        <color rgba="0.113 0.321 0.678 1.0" />
      </material>
    </visual>
    <collision>
      <origin xyz="0.0825 0 0" rpy="0 0 0" />
      <geometry>
        <box size="0.22 0.05 0.08" />
      </geometry>
    </collision>
  </link>

  <!-- Second big link -->
  <link name="iw_beam_top">
    <inertial>
      <mass value="0.151" />
      <inertia ixx="3.8554e-05" ixy="9.4075e-07" ixz="1.709e-06" iyy="4.445e-05" iyz="1.2246e-06" izz="2.5729e-05"/>
    </inertial>
    <visual>
      <origin xyz="-0.165 0 0" rpy="0 0 3.14" />
      <geometry>
        <mesh filename="package://inchworm_description/media/link3.stl" scale="0.001 0.001 0.001" />
      </geometry>
      <material name="blue">
        <color rgba="0.113 0.321 0.678 1.0" />
      </material>
    </visual>
    <collision>
      <origin xyz="-0.0825 0 0" rpy="0 0 0" />
      <geometry>
        <box size="0.22 0.05 0.08" />
      </geometry>
    </collision>
  </link>

  <!-- Link attached to EE -->
  <link name="iw_ankle_top">
    <inertial>
      <mass value="0.151" />
      <inertia ixx="3.8554e-05" ixy="9.4075e-07" ixz="1.709e-06" iyy="4.445e-05" iyz="1.2246e-06" izz="2.5729e-05"/>
    </inertial>
    <visual>
      <origin xyz="-0.055 0 0" rpy="0 0 3.14" />
      <geometry>
        <mesh filename="package://inchworm_description/media/link4.stl" scale="0.001 0.001 0.001" />
      </geometry>
      <material name="blue">
        <color rgba="0.113 0.321 0.678 1.0" />
      </material>
    </visual>
    <collision>
      <origin xyz="-0.02 0 0" rpy="0 0 0" />
      <geometry>
        <box size="0.08 0.045 0.08" />
      </geometry>
    </collision>
  </link>

  <!-- Other foot -->
  <link name="iw_foot_top">
    <inertial>
      <mass value="0.151" />
      <inertia ixx="3.8554e-05" ixy="9.4075e-07" ixz="1.709e-06" iyy="4.445e-05" iyz="1.2246e-06" izz="2.5729e-05"/>
    </inertial>
    <visual>
      <origin xyz="0 0 0" rpy="0 0 0" />
      <geometry>
        <mesh filename="package://inchworm_description/media/link5.stl" scale="0.001 0.001 0.001" />
      </geometry>
      <material name="blue">
        <color rgba="0.113 0.321 0.678 1.0" />
      </material>
    </visual>
    <collision>
      <origin xyz="0 0 -0.027685" rpy="0 0 0" />
      <geometry>
        <box size="0.07 0.07 0.05463" />
      </geometry>
    </collision>
  </link>

  <joint name="foot_to_world" type="fixed">
    <origin xyz="0 0 0.05537" rpy="0 0 0" />

    <parent link="world" />
    <child  link="iw_foot_bottom" />
  </joint>

  <joint name="iw_ankle_foot_bottom" type="revolute">
    <origin xyz="0 0 0.05463" rpy="1.57 0 0" />

    <parent link="iw_foot_bottom" />
    <child  link="iw_ankle_bottom" />

    <axis xyz="0 1 0" />
    <limit effort="10" velocity="1.0" lower="-3.14" upper="3.14" />
  </joint>

  <transmission name="t1">
    <type>transmission_interface/SimpleTransmission</type>
    <joint name="iw_ankle_foot_bottom">
      <hardwareInterface>hardware_interface/EffortJointInterface</hardwareInterface>
    </joint>
    <actuator name="motor1">
      <hardwareInterface>hardware_interface/EffortJointInterface</hardwareInterface>
      <mechanicalReduction>1</mechanicalReduction>
    </actuator>
  </transmission>

  <joint name="iw_beam_ankle_bottom" type="revolute">
    <origin xyz="0 0 -0.001" rpy="0 0 1.57" />

    <parent link="iw_ankle_bottom" />
    <child  link="iw_beam_bottom" />

    <axis xyz="0 0 -1" />
    <limit effort="10" velocity="1.0" lower="-3.14" upper="3.14" />
  </joint>

  <transmission name="t2">
    <type>transmission_interface/SimpleTransmission</type>
    <joint name="iw_beam_ankle_bottom">
      <hardwareInterface>hardware_interface/EffortJointInterface</hardwareInterface>
    </joint>
    <actuator name="motor2">
      <hardwareInterface>hardware_interface/EffortJointInterface</hardwareInterface>
      <mechanicalReduction>1</mechanicalReduction>
    </actuator>
  </transmission>

  <joint name="iw_mid_joint" type="revolute">
    <origin xyz="0.165 0 -0.001" rpy="3.14 0 3.14" />

    <parent link="iw_beam_bottom" />
    <child  link="iw_beam_top" />

    <axis xyz="0 0 1" />
    <limit effort="10" velocity="1.0" lower="-3.14" upper="3.14" />
  </joint>

  <transmission name="t3">
    <type>transmission_interface/SimpleTransmission</type>
    <joint name="iw_mid_joint">
      <hardwareInterface>hardware_interface/EffortJointInterface</hardwareInterface>
    </joint>
    <actuator name="motor3">
      <hardwareInterface>hardware_interface/EffortJointInterface</hardwareInterface>
      <mechanicalReduction>1</mechanicalReduction>
    </actuator>
  </transmission>

  <joint name="iw_beam_ankle_top" type="revolute">
    <origin xyz="-0.165 0 0" rpy="0 0 0" />

    <parent link="iw_beam_top" />
    <child  link="iw_ankle_top" />

    <axis xyz="0 0 1" />
    <limit effort="10" velocity="1.0" lower="-3.14" upper="3.14" />
  </joint>

  <transmission name="t4">
    <type>transmission_interface/SimpleTransmission</type>
    <joint name="iw_beam_ankle_top">
      <hardwareInterface>hardware_interface/EffortJointInterface</hardwareInterface>
    </joint>
    <actuator name="motor4">
      <hardwareInterface>hardware_interface/EffortJointInterface</hardwareInterface>
      <mechanicalReduction>1</mechanicalReduction>
    </actuator>
  </transmission>

  
  <joint name="iw_ankle_foot_top" type="revolute">
    <origin xyz="-0.105 0 0" rpy="0 -1.57 0" />

    <parent link="iw_ankle_top" />
    <child  link="iw_foot_top" />

    <axis xyz="0 0 1" />
    <limit effort="10" velocity="1.0" lower="-3.14" upper="3.14" />
  </joint>

  <transmission name="t5">
    <type>transmission_interface/SimpleTransmission</type>
    <joint name="iw_ankle_foot_top">
      <hardwareInterface>hardware_interface/EffortJointInterface</hardwareInterface>
    </joint>
    <actuator name="motor5">
      <hardwareInterface>hardware_interface/EffortJointInterface</hardwareInterface>
      <mechanicalReduction>1</mechanicalReduction>
    </actuator>
  </transmission>

  <gazebo>
    <plugin name="gazebo_ros_control" filename="libgazebo_ros_control.so">
      <robotNamespace>/inchworm</robotNamespace>
    </plugin>
  </gazebo>
</robot>
